Workbook

Sheet EFFORT LEVEL
A1: BE Name - | C1: FIELD WORK ACTIVITY
A2: H.Q-
A3: S.N. | B3: PARTICULARS | C3: APR | D3: MAY | E3: JUN | F3: JUL | G3: AUG | H3: SEP | I3: OCT | J3: NOV | K3: DEC | L3: JAN | M3: FEB | N3: MAR | O3: CUMM
A4: 1 | B4: NO. OF DAYS IN MONTH | C4: 30 | D4: 31 | E4: 30 | F4: 31 | O4: =SUM(C4:N4) -> 122
A5: 2 | B5: NO. OF AVAILABLE F.W. DAYS | C5: 26 | D5: 25 | E5: 26 | F5: 27 | O5: =SUM(C5:N5) -> 104
A6: 3 | B6: NO. OF ACTUAL F.W. DAYS | C6: 26 | D6: 23 | E6: =26-1-1 -> 24 | F6: 24 | O6: =SUM(C6:N6) -> 97
A7: 4 | B7: NO. OF DAYS ON LEAVE | C7: 0 | D7: 1 | E7: 1 | F7: 1 | O7: =SUM(C7:N7) -> 3
A8: 5 | B8: NO. OF DAYS OF HOLIDAYS | C8: 0 | D8: 1 | F8: 1/0/0 | O8: =SUM(C8:N8) -> 1
A9: 6 | B9: NO. OF DAYS MEETING/ ADMIN /TRANSIT | D9: 1/0/0 | E9: 1/0/0/0 | F9: 1/1/0/0 | O9: =SUM(C9:N9) -> 0
A10: 7 | B10: TOTAL NO. OF DR. CALL | C10: 239 | D10: 209 | E10: 213 | F10: 208 | O10: =SUM(C10:N10) -> 869
A11: 8 | B11: DR. CALL AVERAGE | C11: =C10/C6 -> 9.1923077 | D11: =D10/D6 -> 9.0869565 | E11: =E10/E6 -> 8.875 | F11: =F10/F6 -> 8.6666667 | G11: =G10/G6 -> #DIV/0! | H11: =H10/H6 -> #DIV/0! | I11: =I10/I6 -> #DIV/0! | J11: =J10/J6 -> #DIV/0! | ... O11: =O10/O6 -> 8.9587629
A12: 9 | B12: TOTAL NO. OF CHEMIST CALL | C12: 234 | D12: 208 | E12: 250 | F12: 239 | O12: =SUM(C12:N12) -> 931
A13: 10 | B13: CHEMIST CALL AVERAGE | C13: =C12/C6 -> 9 | D13: =D12/D6 -> 9.0434783 | E13: =E12/E6 -> 10.416667 | F13: =F12/F6 -> 9.9583333 | G13: =G12/G6 -> #DIV/0! | H13: =H12/H6 -> #DIV/0! | I13: =I12/I6 -> #DIV/0! | J13: =J12/J6 -> #DIV/0! | ... O13: =O12/O6 -> 9.5979381
A14: 11 | B14: NO. OF ACTIVITIES ( CAMP, DOB, DOA, RTM, DINNER, CME) | C14: 2/2/4/0/0/0 | D14: 2/6/5/0/0/0) | E14: 3/4/1/0/0/0) | O14: =SUM(C14:N14) -> 0
A15: 12 | B15: NO. OF DR. CONVERSION IN AREA | D15: 1 | E15: 1 | O15: =SUM(C15:N15) -> 2
A16: 13 | B16: NO. OF DRS. ADDED NEW BRAND
A17: 14 | B17: NO. OF DRS. STOPPED
A18: 15 | B18: NO. OF F.W. DAYS WITH MANAGER | C18: 6 | D18: 3 | E18: 3 | O18: =SUM(C18:N18) -> 12
A19: 16 | B19: NO. OF F.W. DAYS INDEPENDENT | C19: 20 | D19: 20 | E19: 21 | O19: =SUM(C19:N19) -> 61

Sheet MONTH FW PROGRESS
A1: BE NAME:
A2: HQ NAME: | E2: MONTH FIELD WORK PROGRESS
E3: NEED TO SEND WEEKLY TO REPORTING MANAGER
A4: DATE | B4: Day | C4: AREA WORKED | D4: TP Submitted | E4: No. of Dr's Met | F4: No. of Chemists/Stockiest Met
A5: 1 | B5: WEDNESDAY | C5: UDAIPUR | E5: 8 | F5: 9
A6: 2 | B6: THURSDAY | C6: UDAIPUR | D6: UDAIPUR | E6: 11 | F6: 6
A7: 3 | B7: FRIDAY | C7: UDAIPUR | D7: UDAIPUR | E7: 9 | F7: 10
A8: 4 | B8: SATURDAY | C8: Jaipur | F8: 13
A10: 6 | B10: MONDAY | C10: UDAIPUR | D10: UDAIPUR | E10: 8 | F10: 10
A11: 7 | B11: TUESDAY | C11: LEAVE
A12: 8 | B12: WEDNESDAY | C12: UDAIPUR | D12: UDAIPUR | E12: 10 | F12: 10
A13: 9 | B13: THURSDAY | C13: UDAIPUR | D13: UDAIPUR | E13: 8 | F13: 10
A14: 10 | B14: FRIDAY | C14: UDAIPUR | D14: UDAIPUR | E14: 16 | F14: 11
A15: 11 | B15: SATURDAY | C15: DUNGARPUR | D15: DUNGARPUR | E15: 8 | F15: 9
A17: 13 | B17: MONDAY | C17: UDAIPUR | D17: UDAIPUR | E17: 7 | F17: 13
B18: TUESDAY | C18: RAJSAMAND | D18: Rajsamand | E18: 9 | F18: 9
A19: 15 | B19: WEDNESDAY | C19: CHITTORGARH | D19: CHITTORGARH | E19: 10 | F19: 11
A20: 16 | B20: THURSDAY | C20: UDAIPUR | D20: UDAIPUR | E20: 10 | F20: 9
A21: 17 | B21: FRIDAY | C21: UDAIPUR | D21: UDAIPUR | E21: 11 | F21: 10
A22: 18 | B22: SATURDAY | C22: DUNGARPUR | D22: DUNGARPUR | E22: 8
A24: 20 | B24: MONDAY | C24: Udaipur | D24: Udaipur | E24: 4 | F24: 11
B25: TUESDAY | C25: RAJSAMAND | D25: RAJSAMAND | E25: 9 | F25: 10
A26: 22 | B26: WEDNESDAY | C26: UDAIPUR | D26: UDAIPUR | E26: 9 | F26: 8
A27: 23 | B27: THURSDAY | C27: UDAIPUR | D27: UDAIPUR | E27: 9 | F27: 9
A28: 24 | B28: FRIDAY | C28: UDAIPUR | D28: UDAIPUR | E28: 14 | F28: 11
A29: 25 | B29: SATURDAY | C29: DUNGARPUR | D29: DUNGARPUR | E29: 8 | F29: 11
A31: 27 | B31: MONDAY | C31: UDAIPUR | D31: UDAIPUR | E31: 3 | F31: 10
B32: TUESDAY | C32: Udaipur | D32: UDAIPUR | E32: 8 | F32: 9
A33: 29 | B33: WEDNESDAY | C33: UDAIPUR | D33: UDAIPUR | E33: 4 | F33: 10
A34: 30 | B34: THURSDAY | C34: UDAIPUR | D34: UDAIPUR | E34: 1 | F34: 0
A35: 31 | B35: FRIDAY | C35: udaipur | D35: udaipur | E35: 6 | F35: 10

Sheet SALES PERFORMANCE
A1: BE Name -
A2: H.Q-
A3: S.N. | B3: PARTICULARS | C3: APR | D3: MAY | E3: JUN | F3: JUL | G3: AUG | H3: SEP | I3: OCT | J3: NOV | K3: DEC | L3: JAN | M3: FEB | N3: MAR | O3: CUMM
A4: 1 | B4: BUDGET | C4: 4.34 | D4: 4.55 | E4: 4.89 | F4: 4.83 | G4: 4.98 | H4: 5.28 | I4: 4.7 | J4: 4.93 | K4: 5.3 | L4: 4.97 | M4: 4.69 | N4: 4.55 | O4: =SUM(C4:N4) -> 58.01
A5: 2 | B5: PRIMARY. 26-27 | C5: 4.34 | D5: 4.75 | E5: 5.07 | F5: 4.84 | O5: =SUM(C5:N5) -> 19
B6: PRIMARY. 25-26 | C6: 4.34 | D6: 4.66 | E6: 4.89 | F6: 4.36 | G6: 4.98 | H6: 1.82 | I6: 4.7 | J6: 4.01 | K6: 2.83 | L6: 3.5 | M6: 3.66 | N6: 2.22 | O6: =SUM(C6:N6) -> 45.97
A7: 3 | B7: % PRM. ACHIVEMENT | C7: =C5/C4% -> 100 | D7: =D5/D4% -> 104.3956 | E7: =E5/E4% -> 103.68098 | F7: =F5/F4% -> 100.20704 | G7: =G5/G4% -> 0 | H7: =H5/H4% -> 0 | I7: =I5/I4% -> 0 | J7: =J5/J4% -> 0 | ... O7: =O5/O4% -> 32.752974
B8: PRIMARY GROWTH | C8: =(C5-C6)/C6% -> 0 | D8: =(D5-D6)/D6% -> 1.9313305 | E8: =(E5-E6)/E6% -> 3.6809816 | F8: =(F5-F6)/F6% -> 11.009174 | G8: =(G5-G6)/G6% -> -100 | H8: =(H5-H6)/H6% -> -100 | I8: =(I5-I6)/I6% -> -100 | J8: =(J5-J6)/J6% -> -100 | ... O8: =(O5-O6)/O6% -> -58.668697
A9: 4 | B9: SECONDARY 26-27 | C9: 5.11 | D9: 4.74 | E9: 5.28 | F9: 4.8 | O9: =SUM(C9:N9) -> 19.93
A10: 5 | B10: SECONDARY 25-26 | C10: 4.06 | D10: 4.44 | E10: 4.48 | F10: 4.95 | G10: 4.51 | H10: 4.28 | I10: 4.53 | J10: 4.47 | K10: 4.72 | L10: 4.73 | M10: 4.04 | N10: 4.51 | O10: =SUM(C10:N10) -> 53.72
A11: 6 | B11: SECONDARY GROWTH | C11: =(C9-C10)/C10% -> 25.862069 | D11: =(D9-D10)/D10% -> 6.7567568 | E11: =(E9-E10)/E10% -> 17.857143 | F11: =(F9-F10)/F10% -> -3.030303 | G11: =(G9-G10)/G10% -> -100 | H11: =(H9-H10)/H10% -> -100 | I11: =(I9-I10)/I10% -> -100 | J11: =(J9-J10)/J10% -> -100 | ... O11: =(O9-O10)/O10% -> -62.900223
A12: 7 | B12: SALES RETURNS | C12: 52875 | D12: 0 | E12: 14244 | F12: 0 | O12: =SUM(C12:N12) -> 67119
A13: 8 | B13: EXPIRY | C13: 37317 | D13: 0 | F13: 26845 | O13: =SUM(C13:N13) -> 64162
A14: 9 | B14: CLOSING STOCK | C14: 5.13 | D14: 8.12 | E14: 7.8 | O14: =SUM(C14:N14) -> 21.05
A15: 10 | B15: INVESTMENT* | C15: 12.5k | D15: 150k | E15: 0 | O15: =SUM(C15:N15) -> 0

Sheet UN.SALES PROG.
C1: HQ NAME:
A2: UNIT SALES PROGRESSION (HQ TOTAL) | D2: APRIL | G2: MAY | H2: MAY | J2: JUN | K2: JUNE | M2: JULY | N2: JULY | P2: AUG | Q2: AUG | S2: SEP | T2: SEP | V2: OCT | W2: OCT | Y2: NOV | Z2: NOV | AB2: DEC | AC2: DEC | AE2: JAN | AF2: JAN | AH2: FEB | AI2: FEB | AK2: MAR | AL2: MARCH
A3: S.N. | B3: PRODUCT NAME | C3: PTS | D3: NET PRI | E3: NET SEC | F3: CLOSING | G3: NET PRI | H3: NET SEC | I3: CLOSING | J3: NET PRI | K3: NET SEC | L3: CLOSING | M3: NET PRI | N3: NET SEC | O3: CLOSING | P3: NET PRI | Q3: NET SEC | R3: CLOSING | S3: NET PRI | T3: NET SEC | U3: CLOSING | V3: NET PRI | W3: NET SEC | X3: CLOSING | Y3: NET PRI | Z3: NET SEC | AA3: CLOSING | AB3: NET PRI | AC3: NET SEC | AD3: CLOSING | AE3: NET PRI | AF3: NET SEC | AG3: CLOSING | AH3: NET PRI | AI3: NET SEC | AJ3: CLOSING | AK3: NET PRI | AL3: NET SEC | AM3: CLOSING
A4: 1 | B4: CALGYM 60K CAPS | C4: 90.16 | D4: 620 | E4: 495 | F4: 385 | G4: 490 | H4: 350 | I4: 147 | J4: 258 | K4: 353 | L4: 308 | M4: 316 | N4: 413 | O4: 329
A5: 2 | B5: CALGYM TAB | C5: 81.78 | D5: 219 | E5: 139 | F5: 260 | G5: 220 | H5: 128 | I5: 143 | J5: 30 | K5: 123 | L5: 254 | M5: 63 | N5: 89 | O5: 260
A6: 3 | B6: CILDIOS 10 TAB | C6: 77.08 | E6: 0 | F6: 0 | H6: 0 | I6: 0 | J6: 0 | K6: 0 | L6: 0 | M6: 0 | N6: 0 | O6: 0
A7: 4 | B7: CILDIOS 20 TAB | C7: 94.29 | J7: 10 | K7: 10 | L7: 0 | M7: 0 | N7: 0 | O7: 10
A8: 5 | B8: CITICURE 500 TAB | C8: 505.6 | E8: 0 | F8: 0 | H8: 0 | I8: 0 | J8: 0 | K8: 0 | L8: 0 | M8: 0 | N8: 0 | O8: 0
A9: 6 | B9: CITICURE PLUS TAB | C9: 517.28 | E9: 2 | F9: 24 | G9: 10 | H9: 8 | I9: 10 | J9: 0 | K9: 0 | L9: 6 | M9: 10 | N9: 10 | O9: 26
A10: 7 | B10: DIOFLAM TAB | C10: 41.72 | E10: 0 | F10: 0 | H10: 0 | I10: 0 | J10: 0 | K10: 0 | L10: 0 | M10: 0 | N10: 0 | O10: 0
A11: 8 | B11: DIOMILIN NT TABLET | C11: 138.36 | D11: 80 | E11: 76 | F11: 91 | G11: 86 | H11: 123 | I11: 47 | J11: 96 | K11: 180 | L11: 153 | M11: 43 | N11: 93 | O11: 120
A12: 9 | B12: DIOSGLT 10 TAB | C12: 145.84 | E12: 8 | F12: 37 | G12: 65 | H12: 39 | I12: 36 | J12: 0 | K12: 15 | L12: 63 | M12: 96 | N12: 45 | O12: 94
A13: 10 | B13: DIOZAM 10 TAB | C13: 60.75 | E13: 0 | F13: 0 | H13: 0 | I13: 0 | J13: 0 | K13: 0 | L13: 0 | M13: 0 | N13: 0 | O13: 0
A14: 11 | B14: DIOZAM 5 TAB | C14: 35.03 | E14: 0 | F14: 0 | H14: 0 | I14: 0 | J14: 0 | K14: 0 | L14: 0 | M14: 0 | N14: 0 | O14: 0
A15: 12 | B15: ESIPRAM 10MG TAB | C15: 65.46 | D15: 186 | E15: 245 | F15: 212 | G15: 170 | H15: 251 | I15: 101 | J15: 230 | K15: 254 | L15: 89 | M15: 116 | N15: 229 | O15: 230
A16: 13 | B16: ESIPRAM PLUS TAB | C16: 105.39 | D16: 274 | E16: 374 | F16: 135 | G16: 269 | H16: 276 | I16: 172 | J16: 315 | K16: 230 | L16: 199 | M16: 143 | N16: 231 | O16: 369
A17: 14 | B17: FITJEE CAPS | C17: 105.16 | D17: 62 | E17: 0 | F17: 10 | G17: 100 | H17: 121 | I17: 19 | J17: 10 | K17: 130 | L17: 19 | M17: 0 | N17: 0 | O17: 0
A18: 15 | B18: FITJEE CAPSULE | C18: 74.08 | E18: 0 | F18: 140 | H18: 0 | I18: 0 | J18: 0 | K18: 0 | L18: 0 | M18: 18 | N18: 11 | O18: 48
A19: 16 | B19: FITJEE DM TABLET | C19: 174.98 | D19: 10 | E19: 20 | F19: 22 | G19: 4 | H19: 8 | I19: 7 | J19: 30 | K19: 16 | L19: 1 | M19: -13 | N19: 3 | O19: 53
A20: 17 | B20: FITJEE Q10 TAB | C20: 365.46 | D20: 10 | E20: 12 | F20: 55 | H20: 14 | I20: 0 | J20: 50 | K20: 25 | L20: 15 | M20: 19 | N20: 9 | O20: 54
A21: 18 | B21: ISIRON CAPS | C21: 63.65 | D21: 90 | E21: 35 | F21: 21 | G21: 30 | H21: 34 | I21: 37 | J21: 10 | K21: 22 | L21: 46 | M21: 0 | N21: 12 | O21: 53
A22: 19 | B22: LINAGET DM TAB | C22: 121.5 | E22: 9 | F22: 44 | G22: 30 | H22: 6 | I22: 18 | J22: 0 | K22: 15 | L22: 33 | M22: 0 | N22: 12 | O22: 21
A23: 20 | B23: LINAGET-5 TAB | C23: 66.47 | E23: 48 | F23: 30 | H23: 17 | I23: 9 | J23: 18 | K23: 18 | L23: 0 | M23: 15 | N23: 46 | O23: 24
A24: 21 | B24: LINAGET-D TAB | C24: 112.44 | E24: 3 | F24: 13 | G24: 24 | H24: 40 | I24: 99 | J24: 15 | K24: 40 | L24: 81 | M24: 53 | N24: 25 | O24: 140
A25: 22 | B25: LINAGET-E25 | C25: 77.08 | D25: 22 | E25: 39 | F25: 46 | H25: 27 | I25: 61 | J25: 20 | K25: 40 | L25: 52 | M25: 120 | N25: 46 | O25: 131
A26: 23 | B26: LINAGET-M-OD5/1000 TAB | C26: 91.93 | E26: 5 | F26: 6 | H26: 0 | I26: 0 | J26: 0 | K26: 6 | L26: 0 | M26: 0 | N26: 0 | O26: 0
A27: 24 | B27: LINAGET-M-OD5/500 TAB | C27: 76.82 | D27: 40 | E27: 40 | F27: 57 | G27: 20 | H27: 9 | I27: 5 | J27: 20 | K27: 46 | L27: 21 | M27: 29 | N27: 16 | O27: 60
A28: 25 | B28: LINAGET-M1000 TAB | C28: 82.93 | E28: 0 | F28: 0 | H28: 0 | I28: 0 | J28: 0 | K28: 0 | L28: 0 | M28: 0 | N28: 0 | O28: 0
A29: 26 | B29: LINAGET-M500 TAB | C29: 62.93 | E29: 9 | F29: 7 | G29: 10 | H29: 31 | I29: 0 | J29: 23 | K29: 21 | L29: 5 | M29: 0 | N29: 8 | O29: 15
A30: 27 | B30: METDIOS25 | C30: 31.32 | J30: 20 | K30: 10 | L30: 0 | M30: 0 | N30: 0 | O30: 20
A31: 28 | B31: METDIOS50 | C31: 37.71 | J31: 17 | K31: 10 | L31: 0 | M31: 0 | N31: 0 | O31: 20
A32: 29 | B32: NEUTOCID DSR CAPS | C32: 66.12 | E32: 0 | F32: 0 | H32: 0 | I32: 0 | J32: 0 | K32: 0 | L32: 0 | M32: 0 | N32: 0 | O32: 0
A33: 30 | B33: NEUTOCID LS TAB | C33: 123.24 | D33: 20 | E33: 10 | F33: 20 | G33: 10 | H33: 11 | I33: 19 | J33: 20 | K33: 12 | L33: 27 | M33: 0 | N33: 6 | O33: 21
A34: 31 | B34: PREMYLIN M 75 TAB | C34: 121.42 | D34: 8 | E34: 134 | F34: 111 | G34: 10 | H34: 46 | I34: 85 | J34: 70 | K34: 92 | L34: 88 | M34: 11 | N34: 117 | O34: 214
A35: 32 | B35: PREMYLIN MSR TAB | C35: 116.68 | D35: 311 | E35: 277 | F35: 309 | G35: 220 | H35: 195 | I35: 229 | J35: 493 | K35: 419 | L35: 69 | M35: 249 | N35: 272 | O35: 366
A36: 33 | B36: PROSTADO D TAB | C36: 184.46 | E36: 6 | F36: 62 | G36: 10 | H36: 26 | I36: 41 | J36: 10 | K36: 16 | L36: 28 | M36: 100 | N36: 74 | O36: 77
A37: 34 | B37: PROSTADO TAB | C37: 60.23 | E37: 0 | F37: 20 | H37: 3 | I37: 17 | J37: 0 | K37: 0 | L37: 0 | M37: 0 | N37: 3 | O37: 29
A38: 35 | B38: SOLEM 250 TAB | C38: 39.39 | E38: 0 | F38: 0 | H38: 0 | I38: 0 | J38: 0 | K38: 0 | L38: 0 | M38: 0 | N38: 0 | O38: 0
A39: 36 | B39: SOLEM 500 TAB | C39: 83.06 | E39: 0 | F39: 0 | G39: 30 | H39: 49 | I39: 0 | J39: 0 | K39: 0 | L39: 0 | M39: 50 | N39: 40 | O39: 50
A40: 37 | B40: VALROS 10 TAB | C40: 93.17 | D40: 90 | E40: 138 | F40: 207 | G40: 75 | H40: 80 | I40: 259 | J40: 150 | K40: 104 | L40: 176 | M40: 35 | N40: 116 | O40: 317
...

Sheet NEAR BY EXPIRY
A1: DETAILS OF PRODUCTS HAVING LESS THAN 8 MONTHS EXPIRY
A2: S. NO | B2: PRODUCT | C2: HQ | D2: STOCKIST NAME | E2: QUANTITY | F2: MONTH OF EXPIRY | G2: PLAN OF LIQUIDATION
A3: 1 | B3: CALGYM 60K CAP
A4: 2 | B4: CALGYM TAB
A5: 3 | B5: CALROS TAB
A6: 4 | B6: CITICURE 500 TAB
A7: 5 | B7: CITICURE PLUS TAB
A8: 6 | B8: DIOFLAM TAB
A9: 7 | B9: DIOMILIN NT TAB
A10: 8 | B10: DIOSGLT 10 TAB
A11: 9 | B11: DIOSUL TAB
A12: 10 | B12: DIOZAM 10 TAB
A13: 11 | B13: DIOZAM 5 TAB
A14: 12 | B14: ESIPRAM 10MG TAB
... A50: 48 | B50: XILDA TAB

Sheet COMMITMENT
A1: COMMITMENT OF MONTH
A2: S.N. | B2: H.Q. NAME | C2: PREVIOUS MONTH BUDGET | D2: PREVIOUS MONTH ACHIV. | E2: CURRENT SECONDARY | F2: CURRENT INVENTORY | G2: CURRENT MONTH BUDGET | H2: COMMITMENT
A3: 1 | B3: UDAIPUR | C3: 4.83 | D3: 4.84 | E3: 4.85 | F3: 7.01 | G3: 4.83 | H3: 5.5
A6: SUPPORT REQUIRE | H6: APRIL | J6: MAY | L6: JUNE
A7: S.N. | B7: H.Q.NAME | C7: DR.NAME | D7: TYPE OF SUPPORT | E7: AMOUNT | F7: EXPECTED ROI | H7: COMMITMENT | I7: ACHIEVEMENT | J7: COMMITMENT | K7: ACHIEVEMENT | L7: COMMITMENT | M7: ACHIEVEMENT
A8: 1 | B8: UDAIPUR | C8: JIMESH PANDYA | D8: GIFT CARDS | E8: 30000 | F8: 15000 | H8: 4.34 | I8: 4.34 | J8: 4.55 | K8: 4.74 | L8: 4.89 | M8: 5.07
A10: 3 | B10: UDAIPUR | C10: VIJAY GOYAL | D10: GIFT CARDS | E10: 10000 | F10: 10000 | H10: JULY | J10: AUGUST | L10: SEPTEMBER
A11: 4 | B11: UDAIPUR | C11: JAYESH GANDHI | D11: SPECIAL PLAN | E11: NOT DECIDED | F11: 50000 | H11: COMMITMENT | I11: ACHIEVEMENT | J11: COMMITMENT | K11: ACHIEVEMENT | L11: COMMITMENT | M11: ACHIEVEMENT
A13: 6 | B13: UDAIPUR | C13: AK VATS | D13: GIFT CARDS | E13: 30000 | F13: 15000
A14: 7 | B14: UDAIPUR | C14: SANDEEP BHATNAGAR | D14: GIFT CARDS | E14: 30000 | F14: 150000 | H14: OCTOBER | J14: NOVEMBER | L14: DECEMBER
A15: 8 | B15: UDAIPUR | C15: RK MALOT | D15: GIFT CARDS | E15: 40000, | F15: 20000 | H15: COMMITMENT | I15: ACHIEVEMENT | J15: COMMITMENT | K15: ACHIEVEMENT | L15: COMMITMENT | M15: ACHIEVEMENT
A17: 10 | B17: UDAIPUR | C17: BS BOMB | D17: GIFT CARDS(VINTEL OR OTHER ) | E17: 30000+20000 | F17: 30000
A18: 11 | B18: UDAIPUR | C18: RAHUL PANCHAL | D18: GIFT CARDS | E18: 30000 | F18: 15000 | H18: JANUARY | J18: FEBRUARY | L18: MARCH
A19: 12 | B19: UDAIPUR | C19: KC JAIN | D19: SPECIAL PLAN | E19: 20000 | H19: COMMITMENT | I19: ACHIEVEMENT | J19: COMMITMENT | K19: ACHIEVEMENT | L19: COMMITMENT | M19: ACHIEVEMENT
A20: 13 | B20: UDAIPUR | C20: DP SINGH | D20: GIFT CARDS | E20: 30000 | F20: 15000
A22: 15 | B22: UDAIPUR | C22: JC DEVPURA | D22: GIFT CARDS | E22: 10000 | F22: 10000
A23: 16 | B23: UDAIPUR | C23: BALDEV MEENA | D23: TREAD MIL | E23: 85000
A24: 17 | B24: UDAIPUR | C24: KRIPA SHANKAR | D24: GIFT CARDS | E24: 20000 | F24: 10000

Sheet WCFYH
A1: WE CARE FOR YOUR HEALTH CAMPAIGN | H1: VISIT DATES
A2: S.NO. | B2: BRAND | C2: NAME OF THE DR. | D2: SPECIALITY | E2: DATE OF CAMPAIGN | F2: CAMPAIGN DONE ON | G2: RX GENERATED | H2: APRIL | I2: MAY | J2: JUNE | K2: JULY | L2: AUG | M2: SEP | N2: OCT | O2: NOV | P2: DEC | Q2: JAN | R2: FEB | S2: MAR
A3: 1 | B3: VINTEL | C3: PRIYANKA MINOCHA | D3: MD MBBS, NEUROLOGY | E3: 10TH OF EVERY MONTH | F3: na
A4: 2 | B4: VINTEL | C4: Mona dingra | D4: DM ENDOCRINOLOGIST | E4: 10TH OF EVERY MONTH | F4: 46213
A5: 3 | B5: VINTEL | C5: UDAY BHOMIK | D5: MCH NEUROSURGERY | E5: 10TH OF EVERY MONTH | F5: 46220
F7: p
A9: 1 | B9: VALROS | C9: DEEPAK AAMETHA | D9: DM CARD. | E9: 20TH OF EVERY MONTH | F9: 46225
A10: 2 | B10: VALROS | C10: MUKESH SHARMA | D10: DM CARD. | E10: 20TH OF EVERY MONTH | F10: 46225
A11: 3 | B11: VALROS | C11: CPPUROHIT | D11: DM CARD. | E11: 20TH OF EVERY MONTH | F11: 46225
A12: 4 | B12: VALROS | C12: RAMESH PATEL | D12: DM CARD. | E12: 20TH OF EVERY MONTH | F12: 46225
A13: 5 | B13: VALROS | C13: Sanjay Gandhi | D13: MS,MCH,CARDIOLOGY | E13: 20TH OF EVERY MONTH
A14: 6 | B14: VALROS | C14: RAVIRAJ SINGH AHADA | D14: DM CARD. | E14: 20TH OF EVERY MONTH | F14: 46225
A15: 7 | B15: VALROS | C15: Dilip jain | D15: DM CARD. | E15: 20TH OF EVERY MONTH | F15: 46226

Sheet A2 GHEE VALROS
A2: PRODUCT NAME | C2: VALROS | D2: A2 GHEE CAMPAIGN | H2: VISIT DATES
A3: S.NO. | B3: DR NAME | C3: HQ | D3: DM CARD | E3: DATE OF ACTIVITY | F3: PRESCRIBER/NON PRESCRIBER | G3: NO. OF PRESCRIPTION/MONTH | H3: APRIL | I3: MAY | J3: JUNE | K3: JULY | L3: AUG | M3: SEP | N3: OCT | O3: NOV | P3: DEC | Q3: JAN | R3: FEB | S3: MAR
A4: 1 | B4: SANJAY GANDHI | C4: UDAIPUR | D4: CARDIOLOGIST | E4: 46186 | F4: NON
A5: 2 | B5: SK KAUSHIQ | C5: UDAIPUR | D5: CARD | E5: 46186 | F5: NON

Sheet TABLE TOP
A1: HQ | B1: TABLE TOP CAMPAIGN
A2: PRODUCT NAME | B2: LINAGET
A3: S.NO. | B3: DR NAME | C3: HQ | D3: SPECIALITY | E3: ACTIVITY DONE/NOT | F3: PRESCRIBER/NON PRESCRIBER | G3: NO. OF PRESCRIPTION/MONTH
A4: 1 | B4: SANDEEP KANSARA | C4: UDAIPUR | D4: ENDO | E4: DONE
A5: 2 | B5: VINOD BOKADIYA | C5: UDAIPUR | D5: ENDO | E5: DONE
A6: 3 | B6: JAI CHORDIYA | C6: UDAIPUR | D6: ENDO
A8: PRODUCT NAME | B8: VINTEL
A9: S.NO. | B9: DR NAME | C9: HQ | D9: SPECIALITY | E9: ACTIVITY DONE/NOT | F9: PRESCRIBER/NON PRESCRIBER | G9: NO. OF PRESCRIPTION/MONTH
A10: 1 | B10: MANISH KULSHRESHT | C10: UDAIPUR | D10: NEURO | E10: Done
A11: 2 | B11: JITESH AGRAWAL | C11: UDAIPUR | D11: PHY | E11: Done
A12: 3 | B12: SATISH CHOUDHARY | C12: UDAIPUR | D12: PHY | E12: Done

Sheet GLUCOMETER CAMP
A1: HQ | B1: GLUCOMETER CAMPAIGN
A2: PRODUCT NAME | B2: LINAGET | H2: NO. OF PRESCRIPTION GENEREATED IN MONTH
A3: S.NO. | B3: DR NAME | D3: HQ | E3: SPECIALITY | F3: CAMP DATE | G3: NO. OF Rx GENERATED IN CAMP | H3: APRIL | I3: MAY | J3: JUNE | K3: JULY | L3: AUG | M3: SEP | N3: OCT | O3: NOV | P3: DEC | Q3: JAN | R3: FEB | S3: MAR
A4: 1 | B4: MONA DHINGRA | D4: UDAIPUR | E4: ENDO
A7: S. NO. | B7: PATIENT NAME | C7: PHONE NO. | E7: BRAND PRESCRIBED | F7: NO. OF STRIPS SOLD ON CAMPAIGN DAY
A8: 1 | B8: OM PRAKASH RANAWAT
A9: 2 | B9: GURUSIKHA SALVI
A10: 3 | B10: nilesh archarta
A11: 4 | B11: kanti lal sharma
A12: 5 | B12: BHERU PRASAD
A13: 6
A14: 7
A15: 8
A16: 9
A17: 10
A18: 11
A19: 12
A20: 13
A21: 14
A22: 15

Sheet SPECIAL FOCUSED BRANDS
A1: HQ
D2: PRIMARY IN STRIPS
A3: S.NO. | B3: PRODUCT NAME | C3: JAN TO MARCH PRIMARY SALE | D3: APRIL | E3: MAY | F3: JUNE | G3: QTR SALE | H3: %GROWTH OVER LAST QTR | I3: JULY | J3: AUG | K3: SEP | L3: QTR SALE | M3: GROWTH OVER LAST QTR | N3: OCT | O3: NOV | P3: DEC | Q3: QTR SALE | R3: GROWTH OVER LAST QTR | S3: JAN | T3: FEB | U3: MAR | V3: QTR SALE | W3: GROWTH OVER LAST QTR
A4: 1 | B4: VINTEL | C4: 3246 | D4: 1650 | E4: 1498 | F4: 2195 | G4: =D4+E4+F4 -> 5343 | H4: =(G4-C4)/C4*100 -> 64.602588 | L4: =I4+J4+K4 -> 0 | M4: =(L4-H4)/H4*100 -> -100 | Q4: =N4+O4+P4 -> 0 | R4: =(Q4-M4)/M4*100 -> -100 | V4: =S4+T4+U4 -> 0 | W4: =(V4-R4)/R4*100 -> -100
A5: 2 | B5: VINVES | D5: 0 | G5: =D5+E5+F5 -> 0 | H5: =(G5-C5)/C5*100 -> #DIV/0! | L5: =I5+J5+K5 -> 0 | M5: =(L5-H5)/H5*100 -> #DIV/0! | Q5: =N5+O5+P5 -> 0 | R5: =(Q5-M5)/M5*100 -> #DIV/0! | V5: =S5+T5+U5 -> 0 | W5: =(V5-R5)/R5*100 -> #DIV/0!
A6: 3 | B6: LINAGET | C6: 214 | D6: 62 | E6: 84 | F6: 96 | G6: =D6+E6+F6 -> 242 | H6: =(G6-C6)/C6*100 -> 13.084112 | L6: =I6+J6+K6 -> 0 | M6: =(L6-H6)/H6*100 -> -100 | Q6: =N6+O6+P6 -> 0 | R6: =(Q6-M6)/M6*100 -> -100 | V6: =S6+T6+U6 -> 0 | W6: =(V6-R6)/R6*100 -> -100
A7: 4 | B7: VALROS | C7: 817 | D7: 352 | E7: 430 | F7: 445 | G7: =D7+E7+F7 -> 1227 | H7: =(G7-C7)/C7*100 -> 50.183599 | L7: =I7+J7+K7 -> 0 | M7: =(L7-H7)/H7*100 -> -100 | Q7: =N7+O7+P7 -> 0 | R7: =(Q7-M7)/M7*100 -> -100 | V7: =S7+T7+U7 -> 0 | W7: =(V7-R7)/R7*100 -> -100
A8: 5 | B8: DIOSGLT | E8: 65 | G8: =D8+E8+F8 -> 65 | H8: =(G8-C8)/C8*100 -> #DIV/0! | L8: =I8+J8+K8 -> 0 | M8: =(L8-H8)/H8*100 -> #DIV/0! | Q8: =N8+O8+P8 -> 0 | R8: =(Q8-M8)/M8*100 -> #DIV/0! | V8: =S8+T8+U8 -> 0 | W8: =(V8-R8)/R8*100 -> #DIV/0!
D11: SECONDARY IN STRIPS
A12: S.NO. | B12: PRODUCT NAME | C12: JAN TO MARCH PRIMARY SALE | D12: APRIL | E12: MAY | F12: JUNE | G12: QTR SALE | H12: %GROWTH OVER LAST QTR | I12: JULY | J12: AUG | K12: SEP | L12: QTR SALE | M12: GROWTH OVER LAST QTR | N12: OCT | O12: NOV | P12: DEC | Q12: QTR SALE | R12: GROWTH OVER LAST QTR | S12: JAN | T12: FEB | U12: MAR | V12: QTR SALE | W12: GROWTH OVER LAST QTR
A13: 1 | B13: VINTEL | C13: =1605+1643+1571 -> 4819 | D13: 2023 | E13: 1709 | F13: 1717 | G13: =D13+E13+F13 -> 5449 | H13: =(G13-C13)/C13*100 -> 13.073252 | L13: =I13+J13+K13 -> 0 | M13: =(L13-H13)/H13*100 -> -100 | Q13: =N13+O13+P13 -> 0 | R13: =(Q13-M13)/M13*100 -> -100 | V13: =S13+T13+U13 -> 0 | W13: =(V13-R13)/R13*100 -> -100
A14: 2 | B14: VINVES | C14: =4+1+16 -> 21 | D14: 2 | G14: =D14+E14+F14 -> 2 | H14: =(G14-C14)/C14*100 -> -90.47619 | L14: =I14+J14+K14 -> 0 | M14: =(L14-H14)/H14*100 -> -100 | Q14: =N14+O14+P14 -> 0 | R14: =(Q14-M14)/M14*100 -> -100 | V14: =S14+T14+U14 -> 0 | W14: =(V14-R14)/R14*100 -> -100
A15: 3 | B15: LINAGET | C15: =107+22+126+132+3 -> 390 | D15: 153 | E15: 130 | F15: 186 | G15: =D15+E15+F15 -> 469 | H15: =(G15-C15)/C15*100 -> 20.25641 | L15: =I15+J15+K15 -> 0 | M15: =(L15-H15)/H15*100 -> -100 | Q15: =N15+O15+P15 -> 0 | R15: =(Q15-M15)/M15*100 -> -100 | V15: =S15+T15+U15 -> 0 | W15: =(V15-R15)/R15*100 -> -100
A16: 4 | B16: VALROS | C16: =401+60+350+423 -> 1234 | D16: 509 | E16: 361 | F16: 502 | G16: =D16+E16+F16 -> 1372 | H16: =(G16-C16)/C16*100 -> 11.183144 | L16: =I16+J16+K16 -> 0 | M16: =(L16-H16)/H16*100 -> -100 | Q16: =N16+O16+P16 -> 0 | R16: =(Q16-M16)/M16*100 -> -100 | V16: =S16+T16+U16 -> 0 | W16: =(V16-R16)/R16*100 -> -100
A17: 5 | B17: DIOSGLT | C17: =56+2+13 -> 71 | D17: 8 | E17: 39 | F17: 15 | G17: =D17+E17+F17 -> 62 | H17: =(G17-C17)/C17*100 -> -12.676056 | L17: =I17+J17+K17 -> 0 | M17: =(L17-H17)/H17*100 -> -100 | Q17: =N17+O17+P17 -> 0 | R17: =(Q17-M17)/M17*100 -> -100 | V17: =S17+T17+U17 -> 0 | W17: =(V17-R17)/R17*100 -> -100

Sheet  FOCUSED BRANDS
A1: HQ
A2: S.NO. | B2: DR NAME | C2: PRODUCT NAME | D2: SPECIALITY | E2: ACTIVITY DONE/NOT | H2: SECONDARY IN STRIPS
F3: PRESCRIBER / NON RXBER | G3: NO. OF PRESCRIPTION GENERATED | H3: APRIL | I3: MAY | J3: JUNE | K3: JULY | L3: AUG | M3: SEP | N3: OCT | O3: NOV | P3: DEC | Q3: JAN | R3: FEB | S3: MAR
A4: 1 | B4: ABHIJEET BASU | C4: CALGYM 60K | D4: GP
A5: 2 | B5: AMIT MEHTA | C5: CALGYM 60K | D5: GP
A6: 3 | B6: ANISH BAHL | C6: CALGYM 60K | D6: GP
A7: 4 | B7: JAGDISH VISHNOI | C7: CALGYM 60K | D7: GP
A8: 5 | B8: LALIT SHREEMALI | C8: CALGYM 60K | D8: GP
A9: 6 | B9: KB BADOLIYA | C9: DIOFLAM | D9: GP
A10: 7 | B10: RAVI MANGALIYA | C10: DIOFLAM | D10: GP
A11: 8 | B11: YN VERMA | C11: DIOFLAM | D11: GP
A12: 9 | B12: RN LADDHA | C12: DIOFLAM | D12: GP
A13: 10 | B13: LALIT SHRIMALI | C13: DIOFLAM | D13: GP
A14: 6 | B14: POOJA GANDHI | C14: FITJEE Q10 | D14: PHY/GYN/GP
A15: 7 | B15: RADHA RASTOGI | C15: FITJEE Q10 | D15: PHY/GYN/GP
... A18: 10 | B18: BS BOMB | C18: FITJEE Q10 | D18: PHY/GYN/GP

Sheet ROI
A1: INVESTMENT AND COVERAGE ANALYSIS .
A2: S.N. | B2: DR.NAME | C2: EXECUTIVE NAME | D2: MOBILE NO. | E2: ACTIVITY TYPE | F2: ACTIVITY AMOUNT | G2: DATE OF ACTIVITY | H2: JAN. | J2: FEB. | L2: MARCH | N2: OLD/NEW | O2: 46023 | Q2: 46054 | S2: 46082 | U2: 46113 | W2: 46143 | Y2: 46174 | AA2: 46204 | AC2: 46235 | AE2: 46266 | AG2: 46296 | AI2: 46327 | AK2: 46357 | AM2: 46388 | AO2: 46419 | AQ2: 46447
H3: DATE | I3: ROI | J3: DATE | K3: ROI | L3: DATE | M3: ROI | O3: DATE of visit | P3: ROI | Q3: DATE of visit | R3: ROI | S3: DATE of visit | T3: ROI | U3: DATE of visit | V3: ROI | W3: DATE of visit | X3: ROI | Y3: DATE of visit | Z3: ROI | AA3: DATE of visit | AB3: ROI | AC3: DATE of visit | AD3: ROI | AE3: DATE of visit | AF3: ROI | AG3: DATE of visit | AH3: ROI | AI3: DATE of visit | AJ3: ROI | AK3: DATE of visit | AL3: ROI | AM3: DATE of visit | AN3: ROI | AO3: DATE of visit | AP3: ROI | AQ3: DATE of visit | AR3: ROI | AS3: OLD/NEW | AT3: TOTAL
A4: 1 | B4: ABHAY JAIN | C4: BANWARI LAL MEENA | D4: 7014694989 | E4: CASH | F4: 50000/120000 | G4: Mar'25,March26 | H4: Jan'24,FEB 25 | O4: 9,17,20,23,27,30 | P4: 10000 | Q4: 17,19,20,27 | R4: 10000 | S4: 9,25,OUT OF TOWN | T4: 10000 | U4: 1,7,10,18,21,24,27,29 | V4: 35000 | W4: 6,8,11,19,26,27,29 | X4: 20000 | Y4: =+MSL!I3 -> 1,2,12,16,18, | Z4: 10000 | AB4: 10000 | AS4: OLD | AT4: 180000
A5: 24 | B5: ABHIJEET BASU | C5: BANWARI LAL MEENA | D5: 9352517070 | E5: GIFT CARDS | F5: 20000, 20000 | G5: May'23,may 26 | O5: 10,12,19 | P5: 0 | Q5: 2,13,17,20,27 | R5: 3000 | S5: 2,5,20,24,27,28 | T5: 0 | U5: 7,9,11,17,24 | V5: 5000 | W5: 4,6,8,15,18 | X5: 3000 | Y5: =+MSL!I4 -> 13,19,29 | Z5: 5000 | AB5: 3000 | AS5: OLD | AT5: 7900
A6: 9 | B6: AK VATS | C6: BANWARI LAL MEENA | D6: 9829279719 | E6: GIFT CARDS | F6: 30000 | G6: May'25 | H6: 01-09-2024,MAY 25 | O6: 8,15,28 | P6: 1300 | Q6: 5,19 | R6: 5000 | S6: 9,19,25 | T6: 6000 | U6: 1,15.,23,30 | V6: 8000 | W6: 6,14,21 | X6: 8000 | Y6: =+MSL!I6 -> 3,18,24 | Z6: 5000 | AB6: 5000 | AS6: OLD | AT6: 86900
A7: 32 | B7: AMIT MEHTA | C7: BANWARI LAL MEENA | D7: 9879188503 | E7: DINNER | F7: 3200 | G7: May'25 | H7: 46023 | O7: 2,10,19,29 | Q7: 20,25 | S7: 5,18 | T7: 3000 | U7: 3,13,17,24,27 | V7: 4500 | W7: 8,15,28,29 | X7: 4000 | Y7: =+MSL!I7 -> 1,3,16 | Z7: 3000 | AB7: 1000 | AS7: NEW | AT7: 6600
A8: 4 | B8: ANISH JAIN | C8: BANWARI LAL MEENA | D8: 9414109022 | E8: GIFT CARDS | F8: 30000 | G8: Apr'25 | O8: NTC | P8: 3000 | R8: 3000 | S8: NTC | T8: 3000 | V8: 7000 | X8: 2000 | Y8: =+MSL!I10 -> 11,na | Z8: 10000 | AB8: 5000 | AS8: NEW | AT8: 105900
A9: 28 | B9: BALDEV MEENA | C9: BANWARI LAL MEENA | D9: 9549609251 | E9: IPHONE | F9: 75000 | G9: Jul'25 | H9: 45627 | O9: 6,8,20,28 | P9: 17000 | Q9: 5,13,24,25 | R9: 21000 | S9: 2,9,17,20,28 | T9: 23000 | U9: 1,2,9,11,18,27 | V9: 22000 | W9: 14,27,28 | X9: 25000 | Y9: =+MSL!I16 -> 12,22,25,29 | Z9: 30000 | AB9: 22000 | AS9: OLD | AT9: 251500
A10: 29 | B10: BHUPESH PARTANI | C10: BANWARI LAL MEENA | D10: 9414741190 | E10: GIFT CARD | F10: 10000 | G10: AUG'24 | H10: 45778 | O10: 5,21 | P10: 0 | Q10: 6 | R10: 0 | S10: 23 | T10: 0 | U10: 6,22 | V10: 0 | W10: 7,22 | X10: 0 | Y10: =+MSL!I17 -> 4,23 | Z10: 0 | AB10: 0 | AS10: OLD | AT10: 20600
A11: 17 | B11: BS BOMB | C11: BANWARI LAL MEENA | D11: 9352500310 | E11: GIFT CARDS | F11: 30000 | G11: May'25 | H11: (9-23),MAY 25 | O11: 9 | P11: 5000 | Q11: 17,21,25 | R11: 6000 | S11: 2,19 | T11: 5000 | U11: 4,11,15 | V11: 6000 | W11: 8,14,18 | X11: 9000 | Y11: =+MSL!I20 -> 1,18 | Z11: 6000 | AB11: 3000 | AS11: OLD | AT11: 94000
A12: 6 | B12: CHIRAG RATHORE | C12: BANWARI LAL MEENA | D12: 9099075657 | E12: GIFT CARDS | F12: 30000 | G12: Apr'24 | H12: Aug'23 | O12: OUT OF TOWN | P12: 2000 | Q12: 7,14,28 | R12: 3000 | S12: 7 | T12: 2000 | U12: 25 | V12: 1000 | W12: 2,16 | X12: 3000 | Y12: =+MSL!I21 -> 6,20,27 | Z12: 2000 | AB12: 3000 | AS12: OLD | AT12: 36000
A13: 14 | B13: DC SHARMA | C13: BANWARI LAL MEENA | D13: 9414159690 | E13: conference | F13: 89000, 150000 | G13: Sep'24,Apr26 | H13: 45536 | O13: 8 | P13: 10000 | Q13: NTC DUE TO SON WED. | R13: 15000 | S13: NTC | T13: 7000 | U13: 3,9,10,NTC | V13: 35000 | W13: 7,12,28 | X13: 40000 | Y13: =+MSL!I23 -> 12,18,ntc | AB13: 28000 | AS13: OLD | AT13: 291100
A14: 33 | B14: DENNY | C14: BANWARI LAL MEENA | D14: 8890644804 | E14: DINNER | F14: 3200, 50000 | G14: May'25,march 26 | O14: 8,19 | P14: 5000 | Q14: 2,13,19,27 | S14: 5,OUT OF TOWN | U14: 9,10,24,30 | V14: 2000 | W14: 8,19,26,29 | X14: 6000 | Y14: =+MSL!I27 -> 12,18,25 | Z14: 0 | AB14: 0 | AS14: NEW | AT14: 5000
A15: 21 | B15: DP SINGH | C15: BANWARI LAL MEENA | D15: 9829164092 | E15: GIFT CARDS | F15: 30000 | G15: May'25 | H15: 45383 | O15: 19,28 | P15: 10000 | Q15: 23,25 | R15: 10000 | S15: 20,31 | T15: 10000 | U15: 7,23,27 | V15: 12000 | W15: 6,11,21,29,30 | X15: 13000 | Y15: =+MSL!I29 -> 15,24,29 | Z15: 5000 | AB15: 5000 | AS15: OLD | AT15: 126200
A16: 35 | B16: GK MUKHIYA | C16: BANWARI LAL MEENA | D16: 8233639147 | E16: GIFT CARDS | F16: 30000 | G16: Nov'25 | O16: 2,9,19,23 | P16: 15000 | Q16: 20,27 | R16: 15000 | S16: 5,28 | T16: 15000 | U16: 3,11,OUT OF TOWN | V16: 12000 | W16: 8,15,29 | X16: 15000 | Y16: =+MSL!I30 -> 13,19,na | Z16: 15000 | AB16: 10000 | AS16: NEW | AT16: 72000
A17: 23 | B17: HEMANT MAHUR | C17: BANWARI LAL MEENA | D17: 9829040103 | E17: GIFT CARDS | F17: 20000 | G17: Jan'26 | H17: 45047 | O17: 19 | P17: 3000 | Q17: 25,27 | R17: 5000 | S17: 25 | T17: 6000 | U17: NA | V17: 7500 | W17: na | X17: 5000 | Y17: =+MSL!I38 -> 0 | Z17: 3000 | AB17: 3000 | AS17: OLD | AT17: 82200
A18: 27 | B18: HITESH YADAV | C18: BANWARI LAL MEENA | D18: 8301865586 | E18: HOTEL | F18: 22000, 6000 | G18: May'24,feb 26 | H18: 45383 | O18: 19 | P18: 3000 | Q18: 5,16,20,27 | R18: 3000 | S18: 9,19,31 | T18: 3000 | U18: 1,10,15 | V18: 7000 | W18: 8,11,28 | X18: 5000 | Y18: =+MSL!I39 -> 12,22,27 | Z18: 3000 | AB18: 3000 | AS18: OLD | AT18: 51700
A19: 7 | B19: JAYESH GANDHI | C19: BANWARI LAL MEENA | D19: 7014111410 | E19: CASH | F19: 100000 | G19: Dec'23, April'24 | H19: Apr'24,JULY 25 | O19: 24 | P19: 30000 | Q19: 7,14,28 | R19: 25000 | S19: 7,21 | T19: 30000 | U19: 25 | V19: 30000 | W19: 2,9,16 | X19: 30000 | Y19: =+MSL!I42 -> 6,10,20,27 | Z19: 30000 | AB19: 30000 | AS19: OLD | AT19: 592000
A20: 26 | B20: JC DEVPURA | C20: BANWARI LAL MEENA | D20: 9829069669 | E20: GIFT CARDS | F20: 10000 | G20: Feb'24 | H20: 01-04-2024,JULY 25 | O20: 28 | P20: 1300 | Q20: 5,19,27 | R20: 5000 | S20: 5,18,19,25 | T20: 6000 | U20: 7,13,18 | V20: 5000 | W20: 12 | X20: 3000 | Y20: =+MSL!I43 -> 2,13,22,29 | Z20: 4000 | AB20: 2000 | AS20: OLD | AT20: 48500
A21: 3 | B21: JIMESH PANDYA | C21: BANWARI LAL MEENA | D21: 9950080606 | E21: GIFT CARDS | F21: 30000 | G21: Mar'25 | O21: 7,22 | P21: 0 | Q21: 18,26 | R21: 0 | S21: 26 | T21: 0 | U21: 8,16 | V21: 3000 | W21: 13,25 | X21: 2000 | Y21: =+MSL!I44 -> 17,26 | Z21: 2000 | AB21: 1000 | AS21: NEW | AT21: 36600
A22: 22 | B22: KAVITA BADJATYA | C22: BANWARI LAL MEENA | D22: 9413954873 | E22: GIFT CARDS | F22: 20000 | G22: Nov'25 | H22: 44866 | O22: 8,23 | P22: 5000 | Q22: 2,16 | R22: 5000 | S22: 2,9,25 | T22: 6000 | U22: 1,7,13,18,20 | V22: 7000 | W22: 4,11,21,27 | X22: 8000 | Y22: =+MSL!I51 -> 9,13,15,22,29 | Z22: 7000 | AB22: 5000 | AS22: OLD | AT22: 99700
A23: 20 | B23: KC JAIN | C23: BANWARI LAL MEENA | D23: 9414162424 | E23: GIFT CARDS | F23: 20000 | G23: Sept'22 | H23: 45505 | O23: 9 | P23: 5000 | Q23: OUT OF TOWN | R23: 7000 | S23: 2,20 | T23: 8000 | U23: 18 | V23: 8000 | X23: 7000 | Y23: =+MSL!I53 -> 0 | Z23: 5000 | AB23: 3000 | AS23: OLD | AT23: 133000
A24: 2 | B24: KIRIT GANDHI | C24: BANWARI LAL MEENA | D24: 7976280712 | E24: CASH | F24: 50000,/50000 | G24: Mar'25,jan 26 | H24: Dec'23, April'24 | O24: 7,22 | P24: 25000 | Q24: 18,26 | R24: 30000 | S24: 26 | T24: 25000 | U24: 8,16 | V24: 20000 | W24: na,25 | X24: 15000 | Y24: =+MSL!I54 -> 17,26 | Z24: 15000 | AB24: 15000 | AS24: OLD | AT24: 319000
A25: 30 | B25: KRIPA SHANKAR | C25: BANWARI LAL MEENA | D25: 9610251730 | E25: GIFT CARDS | F25: 20000 | G25: AUG'24 | H25: 45901 | O25: 5,21 | P25: 0 | Q25: 6 | R25: 0 | S25: 23 | T25: 0 | U25: 6,22 | V25: 0 | W25: 7,22 | X25: 3000 | Y25: =+MSL!I56 -> 4,23 | Z25: 3000 | AB25: 2000 | AS25: OLD | AT25: 20300
A26: 8 | B26: MAHESH DAVE | C26: BANWARI LAL MEENA | D26: 9414471050 | E26: CHEQUE | F26: 30000 | G26: Apr'25 | H26: Sept'22 | O26: 8,28 | P26: 8000 | Q26: 13,25 | R26: 9000 | S26: 17,20 | T26: 8000 | U26: 1,10,17 | V26: 10000 | W26: 15,19,26,30 | X26: 10000 | Y26: =+MSL!I61 -> na,13,25,30 | Z26: 8000 | AB26: 10000 | AS26: OLD | AT26: 134800
A27: 36 | B27: NAVGEET MATHUR | C27: BANWARI LAL MEENA | E27: GIFT CARDS | F27: 20000 | G27: Jan'26 | O27: 2,10,12,19,23 | Q27: 13,20,27 | S27: 20,28 | T27: 3000 | U27: 3,11, OUT OF TOWN | V27: 5000 | W27: out of town | X27: 3000 | Y27: =+MSL!I73 -> na,13,19 | Z27: 4000 | AB27: 2000 | AS27: NEW | AT27: 9800
A28: 11 | B28: PARAS JAIN | C28: BANWARI LAL MEENA | D28: 9829150159 | E28: GIFT CARDS | F28: 40000 | G28: Jan'26 | H28: 01-08-2024,JULY 25 | O28: 2,9,12 | P28: 8000 | Q28: 17,27 | R28: 8000 | S28: 20,31 | T28: 7000 | U28: 4,15,24 | V28: 10000 | W28: 14,26 | X28: 10000 | Y28: =+MSL!I78 -> 1,24 | Z28: 12000 | AB28: 10000 | AS28: OLD | AT28: 81800
A29: 18 | B29: RAHUL PANCHAL | C29: BANWARI LAL MEENA | D29: 8290703766 | E29: GIFT CARDS | F29: 30000 | G29: Feb,25 | H29: 01-09-2024,MAY 25 | O29: 24 | P29: 10000 | Q29: 7,14,28 | R29: 10000 | S29: 7,21 | T29: 10000 | U29: 25 | V29: 5000 | W29: 2,9,16,23 | X29: 15000 | Y29: =+MSL!I87 -> 10,20,27, | Z29: 10000 | AB29: 10000 | AS29: OLD | AT29: 150000
A30: 31 | B30: RAMESH PATEL | C30: BANWARI LAL MEENA | D30: 9530079043 | E30: GIFT CARDS | F30: 50000 | G30: May'25 | H30: 46023 | O30: 8 | P30: 20000 | Q30: 13,19 | R30: 20000 | S30: NTC | T30: 10000 | U30: 1,17,22 | V30: 15000 | W30: 8,15,18,19,29 | X30: 10000 | Y30: =+MSL!I93 -> 12,19,24 | Z30: 15000 | AB30: 12000 | AS30: NEW | AT30: 119600
A31: 15 | B31: RK MALOT | C31: BANWARI LAL MEENA | D31: 9414102661 | E31: GIFT CARDS | F31: 40000, | G31: Aug'23 | H31: (08-2023),MAY 25 | O31: OUT OF TOWN | P31: 10000 | Q31: 18,26 | R31: 10000 | S31: 26 | T31: 10000 | U31: 8,16 | V31: 10000 | W31: 13,25 | X31: 10000 | Y31: =+MSL!I97 -> 17,26 | Z31: 5000 | AB31: 4000 | AS31: OLD | AT31: 129000
A32: 12 | B32: SANDEEP BHATNAGAR | C32: BANWARI LAL MEENA | D32: 9414167693 | E32: GIFT CARDS | F32: 30000 | G32: Apr'24 | H32: 6-24/11-24,JULY 25 | O32: 23,28 | P32: 3000 | Q32: 13,23 | R32: 3000 | S32: NA | T32: 3000 | U32: 2,15,27 | V32: 5000 | W32: 21 | X32: 4500 | Y32: =+MSL!I104 -> 15 | Z32: 0 | AB32: 0 | AS32: OLD | AT32: 42800
A33: 16 | B33: SANDEEP KANSARA | C33: BANWARI LAL MEENA | D33: 9352241126 | E33: CASH | F33: 50000 | G33: May'25 | H33: 45383 | O33: 10 | P33: 10000 | Q33: 25 | R33: 12000 | S33: NTC | T33: 9000 | U33: 11,23 | V33: 10000 | W33: 14,21 | X33: 12000 | Y33: =+MSL!I106 -> 2,9,24 | Z33: 12000 | AB33: 15000 | AS33: OLD | AT33: 145000
A34: 13 | B34: SUMIT SIROYA | C34: BANWARI LAL MEENA | D34: 8529490073 | E34: GIFT CARDS | F34: 40000 | G34: Nov'25 | H34: 45748 | P34: 20000 | Q34: NTC | R34: 20000 | S34: 25 | T34: 20000 | U34: 18 | V34: 25000 | X34: 25000 | Y34: =+MSL!I111 -> 12 | Z34: 30000 | AB34: 30000 | AS34: OLD | AT34: 355000
A35: 5 | B35: VIJAY GOYAL | C35: BANWARI LAL MEENA | D35: 9414026742 | E35: GIFT CARDS | F35: 10000 | G35: Apr'25 | H35: Sep'24,MAY25 | O35: 8,28 | P35: 10000 | Q35: 16, | R35: 15000 | S35: 9,27,31 | T35: 7000 | U35: 4,15 | V35: 5000 | W35: 14 | X35: 5000 | Y35: =+MSL!I118 -> 1 | Z35: 5000 | AB35: 3000 | AS35: NEW | AT35: 51200
A36: 10 | B36: VINOD K RAI | C36: BANWARI LAL MEENA | D36: 9460401750 | E36: HARRISON BOOK | F36: 11000 | G36: Apr'24 | H36: 45474 | O36: 2,8,15,16,23,29 | P36: 30000 | Q36: 5,13,19 | R36: 30000 | S36: 5,19,28 | T36: 30000 | U36: 2,10,17,23,24,30 | V36: 30000 | W36: 8,15,21,28 | X36: 30000 | Y36: =+MSL!I120 -> 12,18,25 | Z36: 40000 | AB36: 40000 | AS36: OLD | AT36: 331500
A37: 19 | B37: VINOD MEHTA | C37: BANWARI LAL MEENA | D37: 9794321171 | E37: GIFT CARDS | F37: 50000 | G37: Jul'25 | H37: 45505 | O37: 2,9,20,23,28 | P37: 10000 | Q37: 5,13,21,27 | R37: 10000 | S37: 6,16,17,25 | T37: 6000 | U37: 2,3,11,17 | V37: 10000 | W37: 14,15,26,29 | X37: 2000 | Y37: =+MSL!I121 -> na,16,18,19,29 | Z37: 20000 | AB37: 15000 | AS37: OLD | AT37: 188000
A38: 37
A39: 38
A40: 39
...

Sheet MSL
G1: VISIT DATES
A2: SrNo | B2: Doctor Name | C2: Activity Type | D2: Speciality | E2: DOB | F2: DOA | G2: APR | H2: MAY | I2: JUN | J2: JUL | K2: AUG | L2: SEPT | M2: OCT | N2: NOV | O2: DEC | P2: JAN | Q2: FEB | R2: MAR
A3: 23 | B3: Abhay jain | C3: CRM | D3: CONSULTANT PHYSICIAN | E3: 12/12/1972 | G3: 1,7,10,17,21,24,27,29 | H3: 6,8,11,19,26,27,29 | I3: 1,2,12,16,18,
A4: 50 | B4: ABHIJEET BASU | D4: MD MED | E4: 12/12/1972 | G4: 7,9,11,17,24 | H4: 4,6,8,15,18 | I4: 13,19,29
A5: 61 | B5: Abhishek Kumar | D5: CONSPHYS | G5: 2,10,17,23,24,28,30 | H5: 15,21,28 | I5: 12,18,25
A6: 10 | B6: AKVATS | C6: CRM | D6: DM NEURO | E6: 02/08/2019 | G6: 1,15,23,30 | H6: 6,14,21 | I6: 3,18,24
A7: 59 | B7: Ameet Mehta | D7: GENERAL PHYSICIAN | E7: 27/04/1900 | F7: 19/05/1900 | G7: 3,13,17,24,27 | H7: 8,15,28,29 | I7: 1,3,16
A8: 37 | B8: AMIT KHANDELWAL | C8: WCFYH VAL/VIN | D8: CARDIO | E8: 03/04/1977 | G8: out of Town ,21
A9: 66 | B9: ANIS JUKARWALA | D9: MD | G9: 1,10,30 | H9: 18,27 | I9: 12,out of town
A10: 20 | B10: ANISH JAIN | C10: CRM | D10: MD MED | E10: 16/12/2019 | I10: 11,na
A11: 86 | B11: ANMOL PAGARIYA | D11: MD MED | E11: 23/01/2019 | G11: 6,22 | H11: 7,22 | I11: 4,23
A12: 96 | B12: ANUBHAV BANSAL | D12: CVTS
A13: 74 | B13: ANURAG JAIN | D13: DNB NEFRO | E13: 12/03/1979 | G13: na | I13: 20
A14: 107 | B14: Ashutosh soni | D14: NEPHRO
A15: 114 | B15: ASHWIN PATIDAR | D15: MBBS MD | G15: 8 | H15: 13,25 | I15: 17,26
A16: 22 | B16: BALDEV MEENA | C16: CRM | D16: MD MED | E16: 05/07/1997 | G16: 1,2,9,11,18,27 | H16: 14,28,27 | I16: 12,22,25,29
A17: 57 | B17: BHUPESH PARTANI | D17: MD MED | E17: 23/10/2019 | G17: 6,22 | H17: 7,22 | I17: 4,23
A18: 113 | B18: BIPIN CHANDRA ADITYA DASARI | D18: CARDIO | E18: 13/05/1990 | G18: 8,16 | H18: ntc,
A19: 111 | B19: BL KUMAWAT | D19: MBBB MD | G19: 6,22 | H19: 22 | I19: 4,23
A20: 6 | B20: BS BOMB | C20: CRM | D20: MD MED | E20: 08/12/2019 | G20: 4,11,15 | H20: 8,14,18 | I20: 1,18
A21: 79 | B21: CHIRAG RATHOR | D21: MD MED | E21: 03/04/1990 | F21: 10/02/2000 | G21: 25 | H21: 2,16 | I21: 6,20,27
A22: 34 | B22: CPPUROHIT | C22: WCFYH VAL/VIN | D22: DM CARDIO | E22: 02/11/1971 | G22: 4,14,21,28 | H22: 12,18 | I22: 20
A23: 7 | B23: D C SHARMA | C23: CRM | D23: DM ENDO | E23: 12/05/2019 | G23: 3,9,10 | H23: 7,12,28 | I23: 12,18,ntc
A24: 108 | B24: DEEPA KATARA | D24: MD PHYSICAN | G24: 8,16 | H24: na,25 | I24: na,26
A25: 32 | B25: DEEPAK AAMETHA | C25: WCFYH VAL/VIN | D25: MD.CARDIO | E25: 17/03/1980 | G25: 7,10,17 | H25: 12,19,26 | I25: 16,19,ntc
A26: 120 | B26: DEEPAK GARG | D26: MBBS PHY | G26: 4 | I26: 20
A27: 12 | B27: DENY | C27: CRM | D27: DM CARDIO | E27: 03/06/2019 | G27: 9,10,24,30(doa) | H27: 8,19,26,29 | I27: 12,18,25
A28: 38 | B28: Dilip jain | C28: WCFYH VAL/VIN | D28: CARDIOLOGY | E28: 24/04/1982 | G28: 4,13,17,21,27 | H28: 18,26,29 | I28: 9,19,29
A29: 2 | B29: DP SINGH | C29: CRM | D29: MD MED | E29: 23/11/2019 | G29: 7,23,27 | H29: 6,11,21,29,30 | I29: 15,24,29
A30: 27 | B30: G K Mukhiya | C30: CRM | D30: DM NEPHRO | E30: 13/05/1973 | G30: 3,11 | H30: 8,15,29 | I30: 13,19,na
A31: 97 | B31: GOURAV KUMAR MITTAL | D31: CARDIO | E31: 11/09/1900 | F31: 23/06/1900 | G31: 27
A32: 75 | B32: GOVIND MANGAL | D32: DM NEURO
A33: 103 | B33: GYANKUMAR DAKSH | D33: General Practitioner (GP) | I33: 11
A34: 116 | B34: HARBEER SINGH CHHABRA | D34: PHY | G34: 3,24 | H34: 29 | I34: 12
A35: 92 | B35: Harish charpota | D35: M B B S PHY | E35: 16/10/1900 | F35: 27/04/1900 | G35: na | H35: 13 | I35: 17,26
A36: 70 | B36: HARISH SANADHY | D36: MD MED | E36: 01/01/1970 | G36: 4,14,21,28 | H36: 12 | I36: 9
A37: 87 | B37: HC SONI | D37: MD MED | E37: 25/10/1955 | F37: 23/11/2023 | G37: 6,22 | H37: 7,22 | I37: 4,23
A38: 21 | B38: HEMANT MAHUR | C38: CRM | D38: MD MED | E38: 25/03/1996 | G38: out of Town
A39: 24 | B39: Hitesh yadav | C39: CRM | D39: CARDIO | E39: 11/05/1900 | F39: 31/01/1900 | G39: 1,10,15 | H39: 8,11,28 | I39: 12,22,27
A40: 76 | B40: JAGDISH VISHNOI | D40: MD MED | E40: 03/03/1974 | G40: 14,21,23,28 | H40: 6,12,19,26 | I40: 2,9,16
...
